<?xml version="1.0" encoding="utf-8"?>
<!-- This URDF was automatically created by SolidWorks to URDF Exporter! Originally created by Stephen Brawner (brawner@gmail.com) 
     Commit Version: 1.6.0-4-g7f85cfe  Build Version: 1.6.7995.38578
     For more information, please see http://wiki.ros.org/sw_urdf_exporter -->
<robot
  name="ASIMOV_FINAL_v3">
  <link
    name="base_link">
    <inertial>
      <origin
        xyz="-0.53586 -0.21063 0.13045"
        rpy="0 0 0" />
      <mass
        value="117.07" />
      <inertia
        ixx="1.3267"
        ixy="6.2294E-05"
        ixz="0.0025483"
        iyy="0.80971"
        iyz="-3.8013E-05"
        izz="1.2349" />
    </inertial>
    <visual>
      <origin
        xyz="0 0 0"
        rpy="0 0 0" />
      <geometry>
        <mesh
          filename="package://ASIMOV_FINAL_v3/meshes/base_link.STL" />
      </geometry>
      <material
        name="">
        <color
          rgba="0.86667 0.9098 1 1" />
      </material>
    </visual>
    <collision>
      <origin
        xyz="0 0 0"
        rpy="0 0 0" />
      <geometry>
        <mesh
          filename="package://ASIMOV_FINAL_v3/meshes/base_link.STL" />
      </geometry>
    </collision>
  </link>
  <link
    name="FL_wheel">
    <inertial>
      <origin
        xyz="-3.2274E-05 -0.024089 9.7242E-05"
        rpy="0 0 0" />
      <mass
        value="0.47815" />
      <inertia
        ixx="0.0011605"
        ixy="-1.2884E-08"
        ixz="-1.8991E-07"
        iyy="0.0021177"
        iyz="3.8596E-08"
        izz="0.001161" />
    </inertial>
    <visual>
      <origin
        xyz="0 0 0"
        rpy="0 0 0" />
      <geometry>
        <mesh
          filename="package://ASIMOV_FINAL_v3/meshes/FL_wheel.STL" />
      </geometry>
      <material
        name="">
        <color
          rgba="1 0.94902 0.9098 1" />
      </material>
    </visual>
    <collision>
      <origin
        xyz="0 0 0"
        rpy="0 0 0" />
      <geometry>
        <mesh
          filename="package://ASIMOV_FINAL_v3/meshes/FL_wheel.STL" />
      </geometry>
    </collision>
  </link>
  <joint
    name="fl-wheel"
    type="continuous">
    <origin
      xyz="-0.057013 0.063627 -0.131"
      rpy="0 0 0" />
    <parent
      link="base_link" />
    <child
      link="FL_wheel" />
    <axis
      xyz="0 1 0" />
    <limit
      effort="10"
      velocity="10" />
    <dynamics
      damping="0.1"
      friction="0.1" />
  </joint>
  <link
    name="FR_wheel">
    <inertial>
      <origin
        xyz="9.9662E-05 0.024089 2.3771E-05"
        rpy="0 0 0" />
      <mass
        value="0.47815" />
      <inertia
        ixx="0.0011611"
        ixy="-3.9581E-08"
        ixz="1.4332E-07"
        iyy="0.0021177"
        iyz="-9.3749E-09"
        izz="0.0011605" />
    </inertial>
    <visual>
      <origin
        xyz="0 0 0"
        rpy="0 0 0" />
      <geometry>
        <mesh
          filename="package://ASIMOV_FINAL_v3/meshes/FR_wheel.STL" />
      </geometry>
      <material
        name="">
        <color
          rgba="1 0.94902 0.9098 1" />
      </material>
    </visual>
    <collision>
      <origin
        xyz="0 0 0"
        rpy="0 0 0" />
      <geometry>
        <mesh
          filename="package://ASIMOV_FINAL_v3/meshes/FR_wheel.STL" />
      </geometry>
    </collision>
  </link>
  <joint
    name="fr-wheel"
    type="continuous">
    <origin
      xyz="-0.057013 -0.48363 -0.13"
      rpy="0 0 0" />
    <parent
      link="base_link" />
    <child
      link="FR_wheel" />
    <axis
      xyz="0 1 0" />
    <limit
      effort="10"
      velocity="10" />
    <dynamics
      damping="0.1"
      friction="0.1" />
  </joint>
  <link
    name="RR_wheel">
    <inertial>
      <origin
        xyz="9.9662E-05 0.024089 2.3771E-05"
        rpy="0 0 0" />
      <mass
        value="0.47815" />
      <inertia
        ixx="0.0011611"
        ixy="-3.9581E-08"
        ixz="1.4332E-07"
        iyy="0.0021177"
        iyz="-9.3749E-09"
        izz="0.0011605" />
    </inertial>
    <visual>
      <origin
        xyz="0 0 0"
        rpy="0 0 0" />
      <geometry>
        <mesh
          filename="package://ASIMOV_FINAL_v3/meshes/RR_wheel.STL" />
      </geometry>
      <material
        name="">
        <color
          rgba="1 0.94902 0.9098 1" />
      </material>
    </visual>
    <collision>
      <origin
        xyz="0 0 0"
        rpy="0 0 0" />
      <geometry>
        <mesh
          filename="package://ASIMOV_FINAL_v3/meshes/RR_wheel.STL" />
      </geometry>
    </collision>
  </link>
  <joint
    name="rr-wheel"
    type="continuous">
    <origin
      xyz="-0.80601 -0.48363 -0.13"
      rpy="0 0 0" />
    <parent
      link="base_link" />
    <child
      link="RR_wheel" />
    <axis
      xyz="0 1 0" />
    <limit
      effort="10"
      velocity="10" />
    <dynamics
      damping="0.1"
      friction="0.1" />
  </joint>
  <link
    name="RL_wheel">
    <inertial>
      <origin
        xyz="0 0 0"
        rpy="0 0 0" />
      <mass
        value="0" />
      <inertia
        ixx="0"
        ixy="0"
        ixz="0"
        iyy="0"
        iyz="0"
        izz="0" />
    </inertial>
    <visual>
      <origin
        xyz="0 0 0"
        rpy="0 0 0" />
      <geometry>
        <mesh
          filename="package://ASIMOV_FINAL_v3/meshes/RL_wheel.STL" />
      </geometry>
      <material
        name="">
        <color
          rgba="1 1 1 1" />
      </material>
    </visual>
    <collision>
      <origin
        xyz="0 0 0"
        rpy="0 0 0" />
      <geometry>
        <mesh
          filename="package://ASIMOV_FINAL_v3/meshes/RL_wheel.STL" />
      </geometry>
    </collision>
  </link>
  <joint
    name="rl-wheel"
    type="continuous">
    <origin
      xyz="-0.80601 0.063627 -0.131"
      rpy="0 0 0" />
    <parent
      link="base_link" />
    <child
      link="RL_wheel" />
    <axis
      xyz="0 1 0" />
    <limit
      effort="10"
      velocity="10" />
    <dynamics
      damping="0.1"
      friction="0.1" />
  </joint>
</robot>